<?xml version="1.0" ?>
<!-- =================================================================================== -->
<!-- |    This document was autogenerated by xacro from sam_auv_into_urdf.xacro        | -->
<!-- |    EDITING THIS FILE BY HAND IS NOT RECOMMENDED                                 | -->
<!-- =================================================================================== -->
<!-- This file is to call the macro defined in sam_auv.urdf.xacro
so that we can generate a concrete urdf file to be imported in Unity-->
<robot name="sam_auv">
  <!-- Links. -->
  <link name="base_link">
    <visual>
      <origin rpy="0 0 0" xyz="-0.677 0 0"/>
      <geometry>
        <mesh filename="mesh/SAM_HULL.dae" scale="1 1 1"/>
      </geometry>
    </visual>
  </link>
  <link name="thruster_link">
    <visual>
      <origin rpy="0 0 0" xyz="0 0 0"/>
      <geometry>
        <mesh filename="mesh/SAM_NOZZLE.dae" scale="1 1 1"/>
      </geometry>
    </visual>
  </link>
  <link name="front_prop_link">
    <visual>
      <origin rpy="0 0 0" xyz="0 0 0"/>
      <geometry>
        <mesh filename="mesh/SAM_FRONTPROP.dae" scale="1 1 1"/>
      </geometry>
    </visual>
  </link>
  <link name="back_prop_link">
    <visual>
      <origin rpy="0 0 0" xyz="0 0 0"/>
      <geometry>
        <mesh filename="mesh/SAM_BACKPROP.dae" scale="1 1 1"/>
      </geometry>
    </visual>
  </link>
  <link name="thruster_yaw_link"/>
  <link name="battery_link"/>
  <link name="tcg1_link"/>
  <link name="tcg2_link"/>
  <link name="pressure_link"/>
  <link name="dvl_link"/>
  <link name="sidescan_link"/>
  <link name="imu_link"/>
  <link name="sbg_link"/>
  <link name="gps_link"/>
  <link name="uw_gps_link"/>
  <link name="camera_down_link"/>
  <link name="camera_front_right_link"/>
  <link name="camera_front_left_link"/>
  <joint name="thruster_yaw_joint" type="revolute">
    <parent link="base_link"/>
    <child link="thruster_yaw_link"/>
    <origin rpy="0.0 0.0 0.0" xyz="-0.677 0.0 0.0"/>
    <axis xyz="0 0 1"/>
    <limit effort="1.0" lower="-0.2" upper="0.2" velocity="0.2"/>
  </joint>
  <joint name="thruster_pitch_joint" type="revolute">
    <parent link="thruster_yaw_link"/>
    <child link="thruster_link"/>
    <origin rpy="0.0 0.0 0.0" xyz="0.0 0.0 0.0"/>
    <axis xyz="0 1 0"/>
    <limit effort="1.0" lower="-0.2" upper="0.2" velocity="0.2"/>
  </joint>
  <joint name="front_prop_joint" type="continuous">
    <!-- <parent link="base_link"/> -->
    <parent link="thruster_yaw_link"/>
    <child link="front_prop_link"/>
    <origin rpy="0.0 0.0 0.0" xyz="-0.0543 0 0"/>
    <axis xyz="1 0 0"/>
  </joint>
  <joint name="back_prop_joint" type="continuous">
    <!-- <parent link="base_link"/> -->
    <parent link="thruster_yaw_link"/>
    <child link="back_prop_link"/>
    <origin rpy="0.0 0.0 0.0" xyz="-0.077 0 0"/>
    <axis xyz="1 0 0"/>
  </joint>
  <joint name="pressure_joint" type="fixed">
    <parent link="base_link"/>
    <child link="pressure_link"/>
    <origin rpy="0.0 0.0 0.0" xyz="-0.503 0.025 0.057"/>
  </joint>
  <joint name="dvl_joint" type="fixed">
    <parent link="base_link"/>
    <child link="dvl_link"/>
    <origin rpy="0.0 0.0 0.0" xyz="0.573 0.0 -0.063"/>
  </joint>
  <!--Sidescan acoustic center, i.e. intersection between both sidescan centers.-->
  <joint name="sidescan_joint" type="fixed">
    <parent link="base_link"/>
    <child link="sidescan_link"/>
    <origin rpy="0.0 0.0 0.0" xyz="-0.043 0.0 0.0"/>
  </joint>
  <joint name="imu_joint" type="fixed">
    <parent link="base_link"/>
    <child link="imu_link"/>
    <origin rpy="0.0 0.0 0.0" xyz="0.24 0.0 -0.036"/>
  </joint>
  <!-- The sbg imu is upside down! -->
  <joint name="sbg_joint" type="fixed">
    <parent link="base_link"/>
    <child link="sbg_link"/>
    <origin rpy="3.1416 0.0 0.0" xyz="0.46 0.0 0.002"/>
  </joint>
  <joint name="gps_joint" type="fixed">
    <parent link="base_link"/>
    <child link="gps_link"/>
    <origin rpy="0.0 0.0 0.0" xyz="0.528 0.0 0.071"/>
  </joint>
  <joint name="uw_gps_joint" type="fixed">
    <parent link="base_link"/>
    <child link="uw_gps_link"/>
    <origin rpy="0.0 0.0 0.0" xyz="-0.402 0.0 0.078"/>
  </joint>
  <joint name="camera_down_joint" type="fixed">
    <parent link="base_link"/>
    <child link="camera_down_link"/>
    <origin rpy="3.1416 0.0 -1.5707" xyz="0.4615 0.0 -0.052"/>
  </joint>
  <joint name="camera_front_left_joint" type="fixed">
    <parent link="base_link"/>
    <child link="camera_front_left_link"/>
    <origin rpy="1.3 3.1416 2.3416" xyz="0.636 0.048 -0.007"/>
  </joint>
  <joint name="camera_front_right_joint" type="fixed">
    <parent link="base_link"/>
    <child link="camera_front_right_link"/>
    <origin rpy="1.3 3.1416 0.8" xyz="0.636 -0.048 -0.007"/>
  </joint>
  <joint name="lcg_joint" type="prismatic">
    <parent link="base_link"/>
    <child link="battery_link"/>
    <origin rpy="0.0 0.0 0.0" xyz="0.083 0.0 0.0"/>
    <axis xyz="1 0 0"/>
    <limit effort="1.0" lower="-0.01" upper="0.01" velocity="0.2"/>
  </joint>
  <joint name="tcg_joint1" type="revolute">
    <parent link="base_link"/>
    <child link="tcg1_link"/>
    <origin rpy="0.0 0.0 0.0" xyz="-0.095 0.0 0.0"/>
    <axis xyz="1 0 0"/>
    <limit effort="1.0" lower="-1.6" upper="1.6" velocity="0.2"/>
  </joint>
  <joint name="tcg_joint2" type="revolute">
    <parent link="base_link"/>
    <child link="tcg2_link"/>
    <origin rpy="0.0 0.0 0.0" xyz="-0.125 0.0 0.0"/>
    <axis xyz="1 0 0"/>
    <limit effort="1.0" lower="-1.6" upper="1.6" velocity="0.2"/>
  </joint>
</robot>
