<?xml version="1.0" ?>
<!-- =================================================================================== -->
<!-- |    This document was autogenerated by xacro from lolo_into_urdf.xacro           | -->
<!-- |    EDITING THIS FILE BY HAND IS NOT RECOMMENDED                                 | -->
<!-- =================================================================================== -->
<robot name="lolo_auv">
  <link name="base_link">
    <visual>
      <origin rpy="0 0 0" xyz="0 0 0"/>
      <geometry>
        <mesh filename="mesh/lolo_hull.dae" scale="1 1 1"/>
      </geometry>
    </visual>
  </link>
  <link name="dvl_link"/>
  <link name="compass_link"/>
  <link name="fls_link"/>
  <link name="imu_link"/>
  <link name="pressure_link"/>
  <link name="gps_link"/>
  <link name="mbes_link"/>
  <link name="usbl_link"/>
  <link name="elevator">
    <visual>
      <origin rpy="0 0 0" xyz="0 0 0"/>
      <geometry>
        <mesh filename="mesh/lolo_elevator.dae" scale="1 1 1"/>
      </geometry>
    </visual>
  </link>
  <link name="rudder_stbd">
    <visual>
      <origin rpy="0 0 0" xyz="0 0 0"/>
      <geometry>
        <mesh filename="mesh/lolo_rudder.dae" scale="1 1 1"/>
      </geometry>
    </visual>
  </link>
  <link name="rudder_port">
    <visual>
      <origin rpy="0 0 0" xyz="0 0 0"/>
      <geometry>
        <mesh filename="mesh/lolo_rudder.dae" scale="1 1 1"/>
      </geometry>
    </visual>
  </link>
  <link name="elevon_stbd">
    <visual>
      <origin rpy="0 0 0" xyz="0 0 0"/>
      <geometry>
        <mesh filename="mesh/lolo_strb_elevon.dae" scale="1 1 1"/>
      </geometry>
    </visual>
  </link>
  <link name="elevon_port">
    <visual>
      <origin rpy="0 0 0" xyz="0 0 0"/>
      <geometry>
        <mesh filename="mesh/lolo_port_elevon.dae" scale="1 1 1"/>
      </geometry>
    </visual>
  </link>
  <link name="thruster_port">
    <visual>
      <origin rpy="0 0 0" xyz="0.0 0 0"/>
      <geometry>
        <mesh filename="mesh/lolo_port_propeller.dae" scale="1 1 1"/>
      </geometry>
    </visual>
  </link>
  <link name="thruster_stbd">
    <visual>
      <origin rpy="0 0 0" xyz="0.0 0 0"/>
      <geometry>
        <mesh filename="mesh/lolo_strb_propeller.dae" scale="1 1 1"/>
      </geometry>
    </visual>
  </link>
  <!-- Mount a 3D pose sensor -->
  <link name="pose_sensor_link">
    <visual>
      <geometry>
        <box size="0.01 0.01 0.01"/>
      </geometry>
    </visual>
  </link>
  <joint name="elevator_joint" type="revolute">
    <origin rpy="0 0 0" xyz="-0.6476 0.0 0.0135"/>
    <parent link="base_link"/>
    <child link="elevator"/>
    <limit effort="0" lower="-0.7853981633974483" upper="0.7853981633974483" velocity="0"/>
    <axis xyz="0 1 0"/>
  </joint>
  <joint name="rudder_stbd_joint" type="revolute">
    <origin rpy="0 0 0" xyz="-0.3278 -0.253 0.129"/>
    <parent link="base_link"/>
    <child link="rudder_stbd"/>
    <limit effort="0" lower="-0.7853981633974483" upper="0.7853981633974483" velocity="0"/>
    <axis xyz="0 0 1"/>
  </joint>
  <joint name="rudder_port_joint" type="revolute">
    <origin rpy="0 0 0" xyz="-0.3278 0.253 0.129"/>
    <parent link="base_link"/>
    <child link="rudder_port"/>
    <limit effort="0" lower="-0.7853981633974483" upper="0.7853981633974483" velocity="0"/>
    <axis xyz="0 0 1"/>
  </joint>
  <joint name="elevon_stbd_joint" type="revolute">
    <origin rpy="0 0 -0.19652" xyz="-0.3733 -0.4035 0.01349"/>
    <parent link="base_link"/>
    <child link="elevon_stbd"/>
    <limit effort="0" lower="-0.7853981633974483" upper="0.7853981633974483" velocity="0"/>
    <axis xyz="0 1 0"/>
  </joint>
  <joint name="elevon_port_joint" type="revolute">
    <origin rpy="0 0 0.19652" xyz="-0.3733 0.4035 0.01349"/>
    <parent link="base_link"/>
    <child link="elevon_port"/>
    <limit effort="0" lower="-0.7853981633974483" upper="0.7853981633974483" velocity="0"/>
    <axis xyz="0 1 0"/>
  </joint>
  <!-- Propeller -->
  <joint name="thruster_stbd_joint" type="continuous">
    <origin rpy="0 0 0" xyz="-0.9056 -0.2754 0.013678"/>
    <axis xyz="1 0 0"/>
    <parent link="base_link"/>
    <child link="thruster_stbd"/>
  </joint>
  <joint name="thruster_port_joint" type="continuous">
    <origin rpy="0 0 0" xyz="-0.9056 0.2754 0.013678"/>
    <axis xyz="1 0 0"/>
    <parent link="base_link"/>
    <child link="thruster_port"/>
  </joint>
  <joint name="pose_sensor_joint" type="revolute">
    <origin rpy="0 0 0" xyz="0 0 0"/>
    <parent link="base_link"/>
    <child link="pose_sensor_link"/>
    <limit effort="0" lower="0" upper="0" velocity="0"/>
  </joint>
  <joint name="dvl_joint" type="fixed">
    <origin rpy="3.14159 0 0" xyz="0.805 -0.025 -0.245"/>
    <parent link="base_link"/>
    <child link="dvl_link"/>
  </joint>
  <joint name="compass_joint" type="fixed">
    <origin rpy="0 0 0" xyz="0 0 0"/>
    <parent link="base_link"/>
    <child link="compass_link"/>
  </joint>
  <joint name="fls_joint" type="fixed">
    <origin rpy="0 0 0" xyz="0 0 0"/>
    <parent link="base_link"/>
    <child link="fls_link"/>
  </joint>
  <joint name="imu_joint" type="fixed">
    <origin rpy="3.14159 0 0" xyz="0 0 0"/>
    <parent link="base_link"/>
    <child link="imu_link"/>
  </joint>
  <joint name="pressure_joint" type="fixed">
    <origin rpy="0 0 0" xyz="0 0 0"/>
    <parent link="base_link"/>
    <child link="pressure_link"/>
  </joint>
  <joint name="gps_joint" type="fixed">
    <origin rpy="0 0 0" xyz="0.836 0 0.44"/>
    <parent link="base_link"/>
    <child link="gps_link"/>
  </joint>
  <joint name="mbes_joint" type="fixed">
    <origin rpy="3.14159 1.53589 0" xyz="2.523 0.0155 -0.302"/>
    <parent link="base_link"/>
    <child link="mbes_link"/>
  </joint>
  <joint name="usbl_joint" type="fixed">
    <origin rpy="0 0 0" xyz="0.389 0.002 0.337"/>
    <parent link="base_link"/>
    <child link="usbl_link"/>
  </joint>
  <!-- <xacro:lolo_auv robot_namespace="$(arg namespace)" debug="$(arg debug)"/> -->
</robot>
